Workbook

Sheet Notes
A1: Cleaning & postcode coding notes
A3: Dataset | B3: Rows in | C3: Rows out | D3: Postcode method
A4: EV chargers (ev_20251216_updated.csv) | B4: 1958 | C4: 1958 | D4: Parsed from street address (1,956); original PCODE used where address had none (1); nearest-point inference (1)
A5: Transport stops (locationfacilitydata.csv) | B5: 797 | C5: 797 | D5: Parsed from address (796); 1 address had no postcode, filled from nearest EV charger
A6: Sports facilities (table.xlsx) | B6: 70 | C6: 70 | D6: Postcode supplied in source
A7: Taxi ranks (taxi-rank-locations_0.csv) | B7: 199 | C7: 198 | D7: No postcode in source. Inferred from nearest EV/transport point with a known postcode. See Postcode_confidence; treat "low" as needing a manual check
A8: Building complexes (BuildingComplexPoint.csv) | B8: 76629 | C8: 76628 | D8: NOT coded: file has no coordinates, address or postcode (only names/codes). Cleaned separately as building_complex_cleaned.csv
A10: Cleaning applied
A11: - Collapsed line breaks / extra whitespace in addresses and text; trimmed; blanks to empty
A12: - EV: removed trailing ", Australia" from addresses; standardised "NRMA Electric" to "NRMA"; added Max_rating_kW (parsed from Charger_rating) and Is_upcoming
A13: - EV: 25 rows had an original PCODE that contradicted the address postcode (e.g. Wilcannia address says 2836, PCODE said 2350). Address postcode used; flagged in PCODE_conflict
A14: - Transport: standardised MORNING_PEAK "6.30-10am" to "6.30am-10am"; deduplicated on TSN
A15: - Sports: postcodes stored as numbers; text tidied
A16: - Buildings: dropped fully empty and constant columns, parsed dates, removed 1 duplicate topoid
A18: Caveats
A19: - 18 transport stops and 2 EV chargers have postcodes outside NSW/ACT (interstate coach stops, e.g. Melbourne, Brisbane). They are genuine, not errors.
A20: - Summary_by_Postcode uses live COUNTIF/SUMIF formulas against the data sheets. Sports facilities cover only City of Sydney area postcodes.

Sheet Summary_by_Postcode
A1: Postcode | B1: EV stations | C1: EV plugs | D1: Transport stops | E1: Sports facilities | F1: Taxi ranks | G1: Total points | H1: Datasets present
A2: 2000 | B2: =COUNTIF(EV_Chargers!$D:$D,A2) -> 29 | C2: =SUMIF(EV_Chargers!$D:$D,A2,EV_Chargers!$I:$I) -> 102 | D2: =COUNTIF(Transport_Stops!$E:$E,A2) -> 22 | E2: =COUNTIF(Sports_Facilities!$C:$C,A2) -> 9 | F2: =COUNTIF(Taxi_Ranks!$B:$B,A2) -> 27 | G2: =B2+D2+E2+F2 -> 87 | H2: =(B2>0)+(D2>0)+(E2>0)+(F2>0) -> 4
A3: 2007 | B3: =COUNTIF(EV_Chargers!$D:$D,A3) -> 3 | C3: =SUMIF(EV_Chargers!$D:$D,A3,EV_Chargers!$I:$I) -> 7 | D3: =COUNTIF(Transport_Stops!$E:$E,A3) -> 0 | E3: =COUNTIF(Sports_Facilities!$C:$C,A3) -> 2 | F3: =COUNTIF(Taxi_Ranks!$B:$B,A3) -> 0 | G3: =B3+D3+E3+F3 -> 5 | H3: =(B3>0)+(D3>0)+(E3>0)+(F3>0) -> 2
A4: 2008 | B4: =COUNTIF(EV_Chargers!$D:$D,A4) -> 2 | C4: =SUMIF(EV_Chargers!$D:$D,A4,EV_Chargers!$I:$I) -> 6 | D4: =COUNTIF(Transport_Stops!$E:$E,A4) -> 1 | E4: =COUNTIF(Sports_Facilities!$C:$C,A4) -> 2 | F4: =COUNTIF(Taxi_Ranks!$B:$B,A4) -> 0 | G4: =B4+D4+E4+F4 -> 5 | H4: =(B4>0)+(D4>0)+(E4>0)+(F4>0) -> 3
A5: 2009 | B5: =COUNTIF(EV_Chargers!$D:$D,A5) -> 2 | C5: =SUMIF(EV_Chargers!$D:$D,A5,EV_Chargers!$I:$I) -> 4 | D5: =COUNTIF(Transport_Stops!$E:$E,A5) -> 8 | E5: =COUNTIF(Sports_Facilities!$C:$C,A5) -> 3 | F5: =COUNTIF(Taxi_Ranks!$B:$B,A5) -> 3 | G5: =B5+D5+E5+F5 -> 16 | H5: =(B5>0)+(D5>0)+(E5>0)+(F5>0) -> 4
A6: 2010 | B6: =COUNTIF(EV_Chargers!$D:$D,A6) -> 8 | C6: =SUMIF(EV_Chargers!$D:$D,A6,EV_Chargers!$I:$I) -> 16 | D6: =COUNTIF(Transport_Stops!$E:$E,A6) -> 1 | E6: =COUNTIF(Sports_Facilities!$C:$C,A6) -> 5 | F6: =COUNTIF(Taxi_Ranks!$B:$B,A6) -> 2 | G6: =B6+D6+E6+F6 -> 16 | H6: =(B6>0)+(D6>0)+(E6>0)+(F6>0) -> 4
A7: 2011 | B7: =COUNTIF(EV_Chargers!$D:$D,A7) -> 3 | C7: =SUMIF(EV_Chargers!$D:$D,A7,EV_Chargers!$I:$I) -> 9 | D7: =COUNTIF(Transport_Stops!$E:$E,A7) -> 2 | E7: =COUNTIF(Sports_Facilities!$C:$C,A7) -> 6 | F7: =COUNTIF(Taxi_Ranks!$B:$B,A7) -> 3 | G7: =B7+D7+E7+F7 -> 14 | H7: =(B7>0)+(D7>0)+(E7>0)+(F7>0) -> 4
A8: 2015 | B8: =COUNTIF(EV_Chargers!$D:$D,A8) -> 8 | C8: =SUMIF(EV_Chargers!$D:$D,A8,EV_Chargers!$I:$I) -> 25 | D8: =COUNTIF(Transport_Stops!$E:$E,A8) -> 3 | E8: =COUNTIF(Sports_Facilities!$C:$C,A8) -> 7 | F8: =COUNTIF(Taxi_Ranks!$B:$B,A8) -> 1 | G8: =B8+D8+E8+F8 -> 19 | H8: =(B8>0)+(D8>0)+(E8>0)+(F8>0) -> 4
A9: 2016 | B9: =COUNTIF(EV_Chargers!$D:$D,A9) -> 2 | C9: =SUMIF(EV_Chargers!$D:$D,A9,EV_Chargers!$I:$I) -> 12 | D9: =COUNTIF(Transport_Stops!$E:$E,A9) -> 0 | E9: =COUNTIF(Sports_Facilities!$C:$C,A9) -> 5 | F9: =COUNTIF(Taxi_Ranks!$B:$B,A9) -> 0 | G9: =B9+D9+E9+F9 -> 7 | H9: =(B9>0)+(D9>0)+(E9>0)+(F9>0) -> 2
A10: 2017 | B10: =COUNTIF(EV_Chargers!$D:$D,A10) -> 6 | C10: =SUMIF(EV_Chargers!$D:$D,A10,EV_Chargers!$I:$I) -> 25 | D10: =COUNTIF(Transport_Stops!$E:$E,A10) -> 1 | E10: =COUNTIF(Sports_Facilities!$C:$C,A10) -> 9 | F10: =COUNTIF(Taxi_Ranks!$B:$B,A10) -> 0 | G10: =B10+D10+E10+F10 -> 16 | H10: =(B10>0)+(D10>0)+(E10>0)+(F10>0) -> 3
A11: 2018 | B11: =COUNTIF(EV_Chargers!$D:$D,A11) -> 3 | C11: =SUMIF(EV_Chargers!$D:$D,A11,EV_Chargers!$I:$I) -> 14 | D11: =COUNTIF(Transport_Stops!$E:$E,A11) -> 0 | E11: =COUNTIF(Sports_Facilities!$C:$C,A11) -> 3 | F11: =COUNTIF(Taxi_Ranks!$B:$B,A11) -> 0 | G11: =B11+D11+E11+F11 -> 6 | H11: =(B11>0)+(D11>0)+(E11>0)+(F11>0) -> 2
A12: 2019 | B12: =COUNTIF(EV_Chargers!$D:$D,A12) -> 3 | C12: =SUMIF(EV_Chargers!$D:$D,A12,EV_Chargers!$I:$I) -> 6 | D12: =COUNTIF(Transport_Stops!$E:$E,A12) -> 0 | E12: =COUNTIF(Sports_Facilities!$C:$C,A12) -> 0 | F12: =COUNTIF(Taxi_Ranks!$B:$B,A12) -> 0 | G12: =B12+D12+E12+F12 -> 3 | H12: =(B12>0)+(D12>0)+(E12>0)+(F12>0) -> 1
A13: 2020 | B13: =COUNTIF(EV_Chargers!$D:$D,A13) -> 11 | C13: =SUMIF(EV_Chargers!$D:$D,A13,EV_Chargers!$I:$I) -> 35 | D13: =COUNTIF(Transport_Stops!$E:$E,A13) -> 3 | E13: =COUNTIF(Sports_Facilities!$C:$C,A13) -> 0 | F13: =COUNTIF(Taxi_Ranks!$B:$B,A13) -> 1 | G13: =B13+D13+E13+F13 -> 15 | H13: =(B13>0)+(D13>0)+(E13>0)+(F13>0) -> 3
... A544: 5000 | B544: =COUNTIF(EV_Chargers!$D:$D,A544) -> 0 | C544: =SUMIF(EV_Chargers!$D:$D,A544,EV_Chargers!$I:$I) -> 0 | D544: =COUNTIF(Transport_Stops!$E:$E,A544) -> 2 | E544: =COUNTIF(Sports_Facilities!$C:$C,A544) -> 0 | F544: =COUNTIF(Taxi_Ranks!$B:$B,A544) -> 0 | G544: =B544+D544+E544+F544 -> 2 | H544: =(B544>0)+(D544>0)+(E544>0)+(F544>0) -> 1
A545: TOTAL | B545: =SUM(B2:B544) -> 1958 | C545: =SUM(C2:C544) -> 5626 | D545: =SUM(D2:D544) -> 797 | E545: =SUM(E2:E544) -> 70 | F545: =SUM(F2:F544) -> 198 | G545: =SUM(G2:G544) -> 3023

Sheet EV_Chargers
A1: OBJECTID | B1: Station_name | C1: Station_address | D1: Postcode | E1: Postcode_source | F1: PCODE_conflict | G1: LGANAME | H1: Operator | I1: Number_of_plugs | J1: Charger_Type | K1: Charger_rating | L1: Max_rating_kW | M1: Is_upcoming | N1: Source | O1: Latitude | P1: Longitude
A2: 1 | C2: 129 Pacific Hwy Ourimbah NSW 2258 | D2: 2258 | E2: parsed from address | F2: =FALSE() -> FALSE | H2: NRMA | I2: 4 | J2: Upcoming | K2: 2x350kW & 2x175kW | L2: 350 | M2: =TRUE() -> TRUE | O2: -33.353198 | P2: 151.36903
A3: 2 | C3: 1-5 Hill Rd Sydney Olympic Park NSW 2127 | D3: 2127 | E3: parsed from address | F3: =FALSE() -> FALSE | H3: NRMA | I3: 8 | J3: Upcoming | K3: 2x350kW & 6x175kW | L3: 350 | M3: =TRUE() -> TRUE | O3: -33.846599 | P3: 151.05673
A4: 3 | C4: 16 Cooper St Macksville NSW 2447 | D4: 2447 | E4: parsed from address | F4: =FALSE() -> FALSE | H4: NRMA | I4: 4 | J4: Upcoming | K4: 2x350kW & 2x175kW | L4: 350 | M4: =TRUE() -> TRUE | O4: -30.708461 | P4: 152.92007
A5: 4 | C5: 2 Macquarie St Parramatta NSW 2150 | D5: 2150 | E5: parsed from address | F5: =FALSE() -> FALSE | H5: NRMA | I5: 4 | J5: Upcoming | K5: 2x350kW & 2x175kW | L5: 350 | M5: =TRUE() -> TRUE | O5: -33.81384 | P5: 150.99951
A6: 5 | C6: 203 Holt Rd Taren Point NSW 2229 | D6: 2229 | E6: parsed from address | F6: =FALSE() -> FALSE | H6: NRMA | I6: 4 | J6: Upcoming | K6: 2x350kW & 2x175kW | L6: 350 | M6: =TRUE() -> TRUE | O6: -34.020269 | P6: 151.1171
A7: 6 | C7: 25 Anglo Rd Campsie NSW 2194 | D7: 2194 | E7: parsed from address | F7: =FALSE() -> FALSE | H7: NRMA | I7: 4 | J7: Upcoming | K7: 2x350kW & 2x175kW | L7: 350 | M7: =TRUE() -> TRUE | O7: -33.911201 | P7: 151.10146
A8: 7 | C8: 29 Church St, Maitland NSW 2320 | D8: 2320 | E8: parsed from address | F8: =FALSE() -> FALSE | H8: NRMA | I8: 4 | J8: Upcoming | K8: 2x350kW & 2x175kW | L8: 350 | M8: =TRUE() -> TRUE | O8: -32.732981 | P8: 151.55356
A9: 8 | C9: 33 Village Cct Gregory Hills NSW 2557 | D9: 2557 | E9: parsed from address | F9: =FALSE() -> FALSE | H9: NRMA | I9: 4 | J9: Upcoming | K9: 2x350kW & 2x175kW | L9: 350 | M9: =TRUE() -> TRUE | O9: -34.026258 | P9: 150.77773
A10: 9 | C10: 37-39 Bong Bong Street,, Dapto NSW 2023 | D10: 2023 | E10: parsed from address | F10: =FALSE() -> FALSE | H10: NRMA | I10: 4 | J10: Upcoming | K10: 2x350kW & 2x175kW | L10: 350 | M10: =TRUE() -> TRUE | O10: -34.494036 | P10: 150.79154
A11: 10 | C11: 3A Cowell St Gladesville NSW 2111 | D11: 2111 | E11: parsed from address | F11: =FALSE() -> FALSE | H11: NRMA | I11: 4 | J11: Upcoming | K11: 2x350kW & 2x175kW | L11: 350 | M11: =TRUE() -> TRUE | O11: -33.832583 | P11: 151.12802
A12: 11 | C12: 50 Pitt St Singleton NSW 2330 | D12: 2330 | E12: parsed from address | F12: =FALSE() -> FALSE | H12: NRMA | I12: 4 | J12: Upcoming | K12: 2x350kW & 2x175kW | L12: 350 | M12: =TRUE() -> TRUE | O12: -32.565117 | P12: 151.17446
A13: 12 | C13: 57 Manchester Rd Gymea NSW 2227 | D13: 2227 | E13: parsed from address | F13: =FALSE() -> FALSE | H13: NRMA | I13: 4 | J13: Upcoming | K13: 2x350kW & 2x175kW | L13: 350 | M13: =TRUE() -> TRUE | O13: -34.032498 | P13: 151.08811
... A16: 15 | C16: Clarence St, Moss Vale NSW 2577 | D16: 2577 | E16: parsed from address | F16: =FALSE() -> FALSE | H16: NRMA | I16: 4 | J16: Upcoming | K16: 2x350kW & 2x175kW | L16: 350 | M16: =TRUE() -> TRUE | O16: -34.548422 | P16: 150.37357
A17: 16 | C17: 1 - 7 Ross St, Wilcannia NSW 2836 | D17: 2836 | E17: parsed from address | F17: =TRUE() -> TRUE | G17: Central Darling Shire Council | H17: NRMA | I17: 4 | J17: DC | K17: 50 kW | L17: 50 | M17: =FALSE() -> FALSE | N17: TfNSW Regional | O17: -31.557629 | P17: 143.38601
A18: 17 | C18: 1 Kendall Ave, Bathurst, 2795 | D18: 2795 | E18: parsed from address | F18: =FALSE() -> FALSE | G18: Bathurst Regional Council | H18: NRMA | I18: 2 | J18: DC | K18: 50 kW | L18: 50 | M18: =FALSE() -> FALSE | N18: Existing Fast Chargers | O18: -33.419102 | P18: 149.58675
A19: 18 | C19: 1 Little Walker St, Casino, NSW 2470 | D19: 2470 | E19: parsed from address | F19: =TRUE() -> TRUE | G19: Richmond Valley Council | H19: NRMA | I19: 4 | J19: DC | K19: 50 kW | L19: 50 | M19: =FALSE() -> FALSE | N19: TfNSW Regional | O19: -28.865732 | P19: 153.04848
A20: 19 | C20: 10W Apsley St, Walcha NSW 2354 | D20: 2354 | E20: parsed from address | F20: =TRUE() -> TRUE | G20: Walcha Council | H20: NRMA | I20: 4 | J20: DC | K20: 50 kW | L20: 50 | M20: =FALSE() -> FALSE | N20: TfNSW Regional | O20: -30.98297 | P20: 151.59282
A21: 20 | C21: 11 Ewingsdale Rd, Ewingsdale, 2481 | D21: 2481 | E21: parsed from address | F21: =FALSE() -> FALSE | G21: Byron Shire Council | H21: NRMA | I21: 4 | J21: DC | K21: 75 kW | L21: 75 | M21: =FALSE() -> FALSE | N21: Existing Fast Chargers | O21: -28.636128 | P21: 153.55346
A22: 21 | C22: 116 Liverpool St, Scone, NSW 2337 | D22: 2337 | E22: parsed from address | F22: =TRUE() -> TRUE | G22: Upper Hunter Shire Council | H22: NRMA | I22: 2 | J22: DC | K22: 50 kW | L22: 50 | M22: =FALSE() -> FALSE | N22: TfNSW Regional | O22: -32.050429 | P22: 150.86667
A23: 22 | C23: 132 Pound Street, Grafton, 2460 | D23: 2460 | E23: parsed from address | F23: =FALSE() -> FALSE | G23: Clarence Valley Council | H23: NRMA | I23: 2 | J23: DC | K23: 50 kW | L23: 50 | M23: =FALSE() -> FALSE | N23: Existing Fast Chargers | O23: -29.68811 | P23: 152.93342
A24: 23 | C24: 134 Lachlan St, Hay, 2711 | D24: 2711 | E24: parsed from address | F24: =FALSE() -> FALSE | G24: Hay Shire Council | H24: NRMA | I24: 4 | J24: DC | K24: 180 kW | L24: 180 | M24: =FALSE() -> FALSE | N24: Existing Fast Chargers | O24: -34.508904 | P24: 144.84279
A25: 24 | C25: 134 Lachlan St, Hay, 2711 | D25: 2711 | E25: parsed from address | F25: =FALSE() -> FALSE | G25: Hay Shire Council | H25: NRMA | I25: 2 | J25: DC | K25: 50 kW | L25: 50 | M25: =FALSE() -> FALSE | N25: Existing Fast Chargers | O25: -34.50908 | P25: 144.84107
A26: 25 | C26: 140 Queen St, Berry, 2535 | D26: 2535 | E26: parsed from address | F26: =FALSE() -> FALSE | G26: Shoalhaven City Council | H26: NRMA | I26: 2 | J26: DC | K26: 50 kW | L26: 50 | M26: =FALSE() -> FALSE | N26: Existing Fast Chargers | O26: -34.775594 | P26: 150.70109
A27: 26 | C27: 15 Victory St, Braidwood, NSW 2622 | D27: 2622 | E27: parsed from address | F27: =TRUE() -> TRUE | G27: Queanbeyan-Palerang Regional Council | H27: NRMA | I27: 4 | J27: DC | K27: 50 kW | L27: 50 | M27: =FALSE() -> FALSE | N27: TfNSW Regional | O27: -35.442778 | P27: 149.79137
A28: 27 | C28: 157 Rouse Street, Tenterfield, NSW 2372 | D28: 2372 | E28: parsed from address | F28: =TRUE() -> TRUE | G28: Tenterfield Shire Council | H28: NRMA | I28: 2 | J28: DC | K28: 50 kW | L28: 50 | M28: =FALSE() -> FALSE | N28: TfNSW Regional | O28: -29.057341 | P28: 152.01889
A29: 28 | C29: 15c Mitchell St, Bourke, NSW 2840 | D29: 2840 | E29: parsed from address | F29: =TRUE() -> TRUE | G29: Bourke Shire Council | H29: NRMA | I29: 4 | J29: DC | K29: 75 kW | L29: 75 | M29: =FALSE() -> FALSE | N29: TfNSW Regional | O29: -30.088397 | P29: 145.93501
A30: 29 | C30: 16 Berry St, Nowra, 2541 | D30: 2541 | E30: parsed from address | F30: =FALSE() -> FALSE | G30: Shoalhaven City Council | H30: NRMA | I30: 4 | J30: DC | K30: 160 kW | L30: 160 | M30: =FALSE() -> FALSE | N30: Existing Fast Chargers | O30: -34.87369 | P30: 150.60038
A31: 30 | C31: 17 Stewart St, Wollongong NSW 2500 | D31: 2500 | E31: parsed from address | F31: =TRUE() -> TRUE | G31: Wollongong City Council | H31: NRMA | I31: 4 | J31: DC | K31: 75 kW | L31: 75 | M31: =FALSE() -> FALSE | N31: TfNSW Regional | O31: -34.428268 | P31: 150.90015
A32: 31 | C32: 18 Dandaloo St, Nyngan, NSW 2825 | D32: 2825 | E32: parsed from address | F32: =TRUE() -> TRUE | G32: Bogan Shire Council | H32: NRMA | I32: 4 | J32: DC | K32: 75 kW | L32: 75 | M32: =FALSE() -> FALSE | N32: TfNSW Regional | O32: -31.564331 | P32: 147.19701
A33: 32 | C33: 2 Perry St, Euston, 2737 | D33: 2737 | E33: parsed from address | F33: =FALSE() -> FALSE | G33: Balranald Shire Council | H33: NRMA | I33: 1 | J33: AC | K33: 22 kW | L33: 22 | M33: =FALSE() -> FALSE | N33: Existing Destination Chargers | O33: -34.577619 | P33: 142.74619
A34: 33 | C34: 2090 Broke Rd, Pokolbin, 2320 | D34: 2320 | E34: parsed from address | F34: =FALSE() -> FALSE | G34: Cessnock City Council | H34: NRMA | I34: 4 | J34: DC | K34: 75 kW | L34: 75 | M34: =FALSE() -> FALSE | N34: Existing Fast Chargers | O34: -32.773429 | P34: 151.29827
A35: 34 | C35: 26 Neilly St, Walgett, NSW 2832 | D35: 2832 | E35: parsed from address | F35: =TRUE() -> TRUE | G35: Walgett Shire Council | H35: NRMA | I35: 2 | J35: DC | K35: 75 kW | L35: 75 | M35: =FALSE() -> FALSE | N35: TfNSW Regional | O35: -30.020699 | P35: 148.11771
A36: 35 | C36: 28 Auburn Street, Moree, NSW 2400 | D36: 2400 | E36: parsed from address | F36: =TRUE() -> TRUE | G36: Moree Plains Shire Council | H36: NRMA | I36: 2 | J36: DC | K36: 50 kW | L36: 50 | M36: =FALSE() -> FALSE | N36: TfNSW Regional | O36: -29.46194 | P36: 149.84066
A37: 36 | C37: 29 Perry St, Euston NSW 2737 | D37: 2737 | E37: parsed from address | F37: =FALSE() -> FALSE | G37: Balranald Shire Council | H37: NRMA | I37: 4 | J37: DC | K37: 175 kW | L37: 175 | M37: =FALSE() -> FALSE | N37: Fast Charging R1 | O37: -34.576596 | P37: 142.74282
A38: 37 | B38: Narrandera Park | C38: 29-55 Twynam St, Narrandera, 2700 | D38: 2700 | E38: parsed from address | F38: =FALSE() -> FALSE | G38: Narrandera Shire Council | H38: NRMA | I38: 4 | J38: DC | K38: 180 kW | L38: 180 | M38: =FALSE() -> FALSE | N38: Existing Fast Chargers | O38: -34.746498 | P38: 146.55008
A39: 38 | B39: Narrandera Park | C39: 29-55 Twynam St, Narrandera, 2700 | D39: 2700 | E39: parsed from address | F39: =FALSE() -> FALSE | G39: Narrandera Shire Council | H39: NRMA | I39: 2 | J39: DC | K39: 50 kW | L39: 50 | M39: =FALSE() -> FALSE | N39: Existing Fast Chargers | O39: -34.746497 | P39: 146.55008
A40: 39 | C40: 2A Beach Rd, Batemans Bay, 2536 | D40: 2536 | E40: parsed from address | F40: =FALSE() -> FALSE | G40: Eurobodalla Shire Council | H40: NRMA | I40: 2 | J40: DC | K40: 50 kW | L40: 50 | M40: =FALSE() -> FALSE | N40: Existing Fast Chargers | O40: -35.708512 | P40: 150.17539
A41: 40 | C41: 3 Broomfield St, Cobar, NSW 2835 | D41: 2835 | E41: parsed from address | F41: =TRUE() -> TRUE | G41: Cobar Shire Council | H41: NRMA | I41: 2 | J41: DC | K41: 50 kW | L41: 50 | M41: =FALSE() -> FALSE | N41: TfNSW Regional | O41: -31.498839 | P41: 145.83761
A42: 41 | B42: Nabiac Park | C42: 35 Nabiac Street, Nabiac NSW 2312 | D42: 2312 | E42: parsed from address | F42: =FALSE() -> FALSE | G42: Mid-Coast Council | H42: NRMA | I42: 2 | J42: DC | K42: 50 kW | L42: 50 | M42: =FALSE() -> FALSE | N42: Existing Fast Chargers | O42: -32.099071 | P42: 152.38157
...

Sheet Transport_Stops
A1: LOCATION_NAME | B1: TSN | C1: EFA_ID | D1: ADDRESS | E1: Postcode | F1: Postcode_source | G1: TRANSPORT_MODE | H1: FACILITIES | I1: ACCESSIBILITY | J1: PHONE | K1: MORNING_PEAK | L1: AFTERNOON_PEAK | M1: SHORT_PLATFORM | N1: LATITUDE | O1: LONGITUDE
A2: Abbotsford Wharf | B2: 2046158 | C2: 10102011 | D2: Great North Rd, Abbotsford NSW 2046 | E2: 2046 | F2: parsed from address | G2: Bus, Ferry | H2: Kiss and ride stopping area | Bike racks | Toilets | Emergency help point | Next service display | I2: This location is Independent Access | Wheelchair ramp boarding assistance | Hearing loop | PA system for announcements | Wharf edge tactiles | M2: =FALSE() -> FALSE | N2: -33.843674 | O2: 151.12817
A3: Aberdeen Station | B3: 233610 | C3: 10101192 | D3: Macqueen St, Aberdeen NSW 2336 | E3: 2336 | F3: parsed from address | G3: Train, Bus, Coach | H3: Commuter car park | Emergency help point | No Opal card top up or single trip ticket sales | I3: This location is Independent Access | Wheelchair ramp boarding assistance | Hearing loop | PA system for announcements | Platform edge tactiles | Stairs | J3: 02 6543 1018 | K3: 6am-10am | L3: 3pm-7pm | M3: =TRUE() -> TRUE | N3: -32.167104 | O3: 150.89205
A4: Adamstown Station | B4: 228920 | C4: 10101159 | D4: Park Ave, Adamstown NSW 2289 | E4: 2289 | F4: parsed from address | G4: Train, Bus | H4: Commuter car park | Wheelchair accessible car space | Kiss and ride stopping area | Bike racks | Emergency help point | Information point | Payphone | No Opal card top up or single trip ticket sales | I4: This location is Independent Access | Wheelchair ramp boarding assistance | Hearing loop | PA system for announcements | Platform edge tactiles | Level crossing | Stairs | Lift | J4: 02 4962 9295 | K4: 6am-10am | L4: 3pm-7pm | M4: =TRUE() -> TRUE | N4: -32.93373 | O4: 151.72008
A5: Adelaide Central Bus Station | B5: 50001 | C5: 10102932 | D5: Franklin St, Adelaide SA 5000 | E5: 5000 | F5: parsed from address | G5: Coach | I5: This location is Not Accessible | | M5: =FALSE() -> FALSE | N5: -34.92748 | O5: 138.5955
A6: Adelong Coach Stop | B6: 272919 | C6: 10102814 | D6: Neill St at Tumut St, Adelong NSW 2729 | E6: 2729 | F6: parsed from address | G6: Coach | I6: This location is Not Accessible | | M6: =FALSE() -> FALSE | N6: -35.308251 | O6: 148.0635
A7: Albion Park Station | B7: 252710 | C7: 10101381 | D7: Princes Hwy, Albion Park Rail NSW 2527 | E7: 2527 | F7: parsed from address | G7: Train, Bus | H7: Commuter car park | Wheelchair accessible car space | Kiss and ride stopping area | Bike racks | Toilets | Wheelchair accessible toilet | Baby change table | Emergency help point | Payphone | Opal card top up or single trip ticket machine (Card Payment only) | I7: This location is Assisted Access | Wheelchair ramp boarding assistance | PA system for announcements | Platform edge tactiles | Level crossing | Stairs | J7: 02 4223 5416 | K7: 6am-10am | L7: 3pm-7pm | M7: =TRUE() -> TRUE | N7: -34.562647 | O7: 150.7985
A8: Albury Station | B8: 26401 | C8: 10101849 | D8: Railway Pl, East Albury NSW 2640 | E8: 2640 | F8: parsed from address | G8: Train, Coach, Taxi | H8: Commuter car park | Wheelchair accessible car space | Kiss and ride stopping area | Taxi rank | Bike racks | Toilets | Wheelchair accessible toilet | Baby change table | Emergency help point | Information point | Payphone | Next service display | I8: This location is Independent Access | Wheelchair ramp boarding assistance | Hearing loop | Hearing loop (ticket counter) | PA system for announcements | Platform edge tactiles | Stairs | M8: =FALSE() -> FALSE | N8: -36.084068 | O8: 146.92469
A9: Alectown Coach Stop | B9: 2870731 | C9: 10102823 | D9: Goobang St before Cross St, Alectown NSW 2870 | E9: 2870 | F9: parsed from address | G9: Coach | I9: This location is Not Accessible | | M9: =FALSE() -> FALSE | N9: -32.933121 | O9: 148.24023
A10: Allawah Station | B10: 222020 | C10: 10101338 | D10: Railway Pde, Allawah NSW 2218 | E10: 2218 | F10: parsed from address | G10: Train, Bus | H10: Commuter car park | Wheelchair accessible car space | Kiss and ride stopping area | Bike racks | Toilets | Wheelchair accessible toilet | Baby change table | Emergency help point | Payphone | Next service display | Opal card top up or single trip ticket machine (Cash or Card Payment) | I10: This location is Independent Access | Wheelchair ramp boarding assistance | Hearing loop | PA system for announcements | Platform edge tactiles | Stairs | Lift | J10: 02 9563 7415 | K10: 6am-10am | L10: 3pm-7pm | M10: =FALSE() -> FALSE | N10: -33.969584 | O10: 151.11433
A11: Allworth Coach Stop | B11: 2425101 | C11: 10102780 | D11: The Bucketts Way opp Allworth Rd, Allworth NSW 2425 | E11: 2425 | F11: parsed from address | G11: Coach | I11: This location is Not Accessible | | M11: =FALSE() -> FALSE | N11: -32.531345 | O11: 151.9442
A12: Alstonville Coach Stop | B12: 2477393 | C12: 10102751 | D12: Main St at Daley St, Alstonville NSW 2477 | E12: 2477 | F12: parsed from address | G12: Coach | I12: This location is Not Accessible | | M12: =FALSE() -> FALSE | N12: -28.8418 | O12: 153.44001
A13: Ardlethan Coach Stop | B13: 266590 | C13: 10102847 | D13: Ariah St before Yithan St, Ardlethan NSW 2665 | E13: 2665 | F13: parsed from address | G13: Coach | I13: This location is Not Accessible | | M13: =FALSE() -> FALSE | N13: -34.357807 | O13: 146.90256
A14: Ariah Park Coach Stop | B14: 266591 | C14: 10102849 | D14: Ariah Park Post Office, Coolamon St, Ariah Park NSW 2665 | E14: 2665 | F14: parsed from address | G14: Coach | I14: This location is Not Accessible | | M14: =FALSE() -> FALSE | N14: -34.347706 | O14: 147.22108
A15: Arlington Light Rail | B15: 220322 | C15: 10101623 | D15: Constitution Rd, Dulwich Hill NSW 2203 | E15: 2203 | F15: parsed from address | G15: Light rail | H15: Kiss and ride stopping area | Bike racks | Emergency help point | I15: This location is Independent Access | Hearing loop | PA system for announcements | Platform edge tactiles | Level crossing | Stairs | K15: 6.30am-10am | L15: 3pm-7pm | M15: =FALSE() -> FALSE | N15: -33.901841 | O15: 151.13806
A16: Armidale Station | B16: 23501 | C16: 10101819 | D16: Brown St, Armidale NSW 2350 | E16: 2350 | F16: parsed from address | G16: Train, Coach, Taxi | H16: Commuter car park | Wheelchair accessible car space | Kiss and ride stopping area | Taxi rank | Bike racks | Toilets | Wheelchair accessible toilet | Baby change table | Emergency help point | Information point | Next service display | I16: This location is Independent Access | Wheelchair ramp boarding assistance | Hearing loop | PA system for announcements | Platform edge tactiles | Stairs | M16: =FALSE() -> FALSE | N16: -30.515373 | O16: 151.65175
A17: Armidale Town Coach Stop | B17: 2350869 | C17: 10102867 | D17: Central Beardy Mall, Faulkner St, Armidale NSW 2350 | E17: 2350 | F17: parsed from address | G17: Coach | I17: This location is Not Accessible | | M17: =FALSE() -> FALSE | N17: -30.513408 | O17: 151.66715
A18: Arncliffe Station | B18: 220520 | C18: 10101333 | D18: Firth St, Arncliffe NSW 2205 | E18: 2205 | F18: parsed from address | G18: Train, Bus, Taxi | H18: Commuter car park | Wheelchair accessible car space | Kiss and ride stopping area | Taxi rank | Bike racks | Toilets | Wheelchair accessible toilet | Baby change table | Emergency help point | Payphone | Next service display | Opal card top up or single trip ticket machine (Card Payment only) | I18: This location is Independent Access | Wheelchair ramp boarding assistance | Hearing loop | PA system for announcements | Platform edge tactiles | Stairs | Lift | J18: 02 9563 7431 | K18: 6.30am-10am | L18: 3pm-7pm | M18: =FALSE() -> FALSE | N18: -33.936456 | O18: 151.1473
A19: Artarmon Station | B19: 206410 | C19: 10101116 | D19: Hampden Rd, Artarmon NSW 2064 | E19: 2064 | F19: parsed from address | G19: Train, Taxi | H19: Wheelchair accessible car space | Kiss and ride stopping area | Taxi rank | Bike racks | Bike lockers | Wheelchair accessible toilet | Baby change table | Emergency help point | Payphone | Next service display | Opal card top up or single trip ticket machine (Card Payment only) | I19: This location is Independent Access | Wheelchair ramp boarding assistance | Hearing loop | PA system for announcements | Platform edge tactiles | Stairs | Lift | J19: 02 9379 1140 | K19: 6.30am-10am | L19: 3pm-7pm | M19: =TRUE() -> TRUE | N19: -33.808903 | O19: 151.18529
A20: Ashfield Station | B20: 213110 | C20: 10101209 | D20: Brown St, Ashfield NSW 2131 | E20: 2131 | F20: parsed from address | G20: Train, Bus, Taxi | H20: Commuter car park | Transport Park&Ride | Wheelchair accessible car space | Kiss and ride stopping area | Taxi rank | Bike racks | Bike lockers | Bike shed | Toilets | Wheelchair accessible toilet (MLAK) | Baby change table | Emergency help point | Payphone | Next service display | Opal card top up or single trip ticket machine (Card Payment only) | Opal card top up machine (Card Payment only) | I20: This location is Independent Access | Wheelchair ramp boarding assistance | Hearing loop | PA system for announcements | Platform edge tactiles | Stairs | Lift | J20: 02 9752 8356 | K20: 6.30am-10am | L20: 3pm-7pm | M20: =FALSE() -> FALSE | N20: -33.887551 | O20: 151.1255
A21: Asquith Station | B21: 207730 | C21: 10101128 | D21: Haldane St, Asquith NSW 2077 | E21: 2077 | F21: parsed from address | G21: Train | H21: Commuter car park | Wheelchair accessible car space | Kiss and ride stopping area | Toilets | Emergency help point | Payphone | Next service display | Opal card top up or single trip ticket machine (Card Payment only) | I21: This location is Assisted Access | Wheelchair ramp boarding assistance | Hearing loop | PA system for announcements | Platform edge tactiles | J21: 02 9847 8495 | K21: 6.30am-10am | L21: 3pm-7pm | M21: =TRUE() -> TRUE | N21: -33.68877 | O21: 151.10803
A22: Attunga Coach Stop | B22: 234523 | C22: 10102700 | D22: Fossickers Way at Ridge St, Attunga NSW 2345 | E22: 2345 | F22: parsed from address | G22: Coach | I22: This location is Not Accessible | | M22: =FALSE() -> FALSE | N22: -30.92869 | O22: 150.84584
A23: Auburn Station | B23: 214410 | C23: 10101219 | D23: Rawson St, Auburn NSW 2144 | E23: 2144 | F23: parsed from address | G23: Train, Bus, Taxi | H23: Wheelchair accessible car space | Kiss and ride stopping area | Taxi rank | Bike racks | Bike lockers | Toilets | Wheelchair accessible toilet (MLAK) | Baby change table | Emergency help point | Payphone | Next service display | Opal card top up or single trip ticket machine (Card Payment only) | Opal card top up machine (Card Payment only) | I23: This location is Independent Access | Wheelchair ramp boarding assistance | Hearing loop | PA system for announcements | Platform edge tactiles | Stairs | Lift | J23: 02 9848 9206 | K23: 6.30am-10am | L23: 3pm-7pm | M23: =FALSE() -> FALSE | N23: -33.84927 | O23: 151.03287
A24: Austinmer Station | B24: 251540 | C24: 10101363 | D24: Railway Ave, Austinmer NSW 2515 | E24: 2515 | F24: parsed from address | G24: Train, Bus | H24: Commuter car park | Wheelchair accessible car space | Toilets | Emergency help point | Payphone | No Opal card top up or single trip ticket sales | I24: This location is Assisted Access | Wheelchair ramp boarding assistance | Hearing loop | PA system for announcements | Platform edge tactiles | J24: 02 4223 5573 | K24: 6.30am-10am | L24: 3pm-7pm | M24: =TRUE() -> TRUE | N24: -34.30641 | O24: 150.92931
A25: Awaba Station | B25: 228310 | C25: 10101150 | D25: Adelaide St, Awaba NSW 2283 | E25: 2283 | F25: parsed from address | G25: Train, Bus | H25: Commuter car park | Emergency help point | Information point | No Opal card top up or single trip ticket sales | I25: This location is Not Accessible | Wheelchair ramp boarding assistance | Hearing loop | PA system for announcements | Stairs | J25: 02 4349 9241 | K25: 6.30am-10am | L25: 3pm-7pm | M25: =TRUE() -> TRUE | N25: -33.01292 | O25: 151.54163
A26: Ballina Coach Stop | B26: 2478673 | C26: 10102749 | D26: Tamar St before Moon St, Ballina NSW 2478 | E26: 2478 | F26: parsed from address | G26: Bus, Coach | I26: This location is Not Accessible | | M26: =FALSE() -> FALSE | N26: -28.86933 | O26: 153.56059
A27: Ballina West Coach Stop | B27: 2478675 | C27: 10102750 | D27: West Tower Tavern, River St, West Ballina NSW 2478 | E27: 2478 | F27: parsed from address | G27: Bus, Coach | I27: This location is Not Accessible | | M27: =FALSE() -> FALSE | N27: -28.864101 | O27: 153.53393
A28: Balmain East Wharf | B28: 20414 | C28: 10102010 | D28: Darling St, Balmain East NSW 2041 | E28: 2041 | F28: parsed from address | G28: Bus, Ferry | H28: Emergency help point | Next service display | Opal card top up or single trip ticket machine (Card Payment only) | I28: This location is Independent Access | Wheelchair ramp boarding assistance | Hearing loop | PA system for announcements | Wharf edge tactiles | Stairs | M28: =FALSE() -> FALSE | N28: -33.856967 | O28: 151.19598
A29: Balmain West Wharf | B29: 204155 | C29: 10102006 | D29: Elliott St, Balmain West NSW 2041 | E29: 2041 | F29: parsed from address | G29: Ferry | H29: Toilets | Wheelchair accessible toilet | Emergency help point | Information point | Next service display | I29: This location is Assisted Access | Wheelchair ramp boarding assistance | Hearing loop | Wharf edge tactiles | M29: =FALSE() -> FALSE | N29: -33.855082 | O29: 151.16875
A30: Balmain Wharf | B30: 204157 | C30: 10102008 | D30: Thames St, Balmain NSW 2041 | E30: 2041 | F30: parsed from address | G30: Ferry | H30: Wheelchair accessible car space | Kiss and ride stopping area | Bike racks | Emergency help point | Next service display | Opal card top up or single trip ticket machine (Card Payment only) | I30: This location is Independent Access | Wheelchair ramp boarding assistance | Hearing loop | PA system for announcements | Wharf edge tactiles | M30: =FALSE() -> FALSE | N30: -33.854716 | O30: 151.18636
A31: Balranald Coach Stop | B31: 271512 | C31: 10102854 | D31: Balranald Information Centre, Market St, Balranald NSW 2715 | E31: 2715 | F31: parsed from address | G31: Coach | I31: This location is Not Accessible | | M31: =FALSE() -> FALSE | N31: -34.640572 | O31: 143.56464
A32: Bangalow Coach Stop | B32: 2479103 | C32: 10102740 | D32: Station St at Byron St, Bangalow NSW 2479 | E32: 2479 | F32: parsed from address | G32: Coach | I32: This location is Not Accessible | | M32: =FALSE() -> FALSE | N32: -28.686545 | O32: 153.5248
A33: Bank Street Light Rail | B33: 200952 | C33: 10101635 | D33: Miller St, Pyrmont NSW 2009 | E33: 2009 | F33: parsed from address | G33: Light rail | H33: Emergency help point | Opal card top up or single trip ticket machine (Card Payment only) | I33: This location is Independent Access | PA system for announcements | Platform edge tactiles | Level crossing | Stairs | Lift | K33: 6.30am-10am | L33: 3pm-7pm | M33: =FALSE() -> FALSE | N33: -33.870917 | O33: 151.19229
A34: Banksia Station | B34: 221610 | C34: 10101334 | D34: Hattersley St, Banksia NSW 2216 | E34: 2216 | F34: parsed from address | G34: Train, Bus, Taxi | H34: Wheelchair accessible car space | Kiss and ride stopping area | Taxi rank | Toilets | Wheelchair accessible toilet | Baby change table | Emergency help point | Next service display | Opal card top up or single trip ticket machine (Card Payment only) | I34: This location is Independent Access | Wheelchair ramp boarding assistance | Hearing loop | PA system for announcements | Platform edge tactiles | Stairs | Lift | J34: 02 9563 7429 | K34: 6.30am-10am | L34: 3pm-7pm | M34: =FALSE() -> FALSE | N34: -33.945286 | O34: 151.14043
A35: Bankstown Station | B35: 220010 | C35: 10101401 | D35: North Tce, Bankstown NSW 2200 | E35: 2200 | F35: parsed from address | G35: Train, Bus, Taxi | H35: Commuter car park | Wheelchair accessible car space | Kiss and ride stopping area | Taxi rank | Bike racks | Bike lockers | Toilets | Wheelchair accessible toilet | Baby change table | Emergency help point | Payphone | Next service display | Opal card top up or single trip ticket machine (Card Payment only) | Opal card top up machine (Card Payment only) | Free mobile phone charging | I35: This location is Independent Access | Wheelchair ramp boarding assistance | PA system for announcements | Platform edge tactiles | Stairs | Lift | J35: 02 9563 7160 | K35: 6.30am-10am | L35: 3pm-7pm | M35: =FALSE() -> FALSE | N35: -33.917865 | O35: 151.03469
A36: Baradine Coach Stop | B36: 239612 | C36: 10102664 | D36: Wellington St at Darling St, Baradine NSW 2396 | E36: 2396 | F36: parsed from address | G36: Coach | I36: This location is Not Accessible | | M36: =FALSE() -> FALSE | N36: -30.949333 | O36: 149.06651
A37: Barangaroo Station | B37: 200046 | C37: 10101513 | D37: Hickson Rd, Barangaroo NSW 2000 | E37: 2000 | F37: parsed from address | G37: Metro, Bus, Ferry, Taxi | H37: Bike shed | Bike racks | Kiss and ride stopping area | Opal card top up or single trip ticket machine (Card Payment only) | Wheelchair accessible toilet | Baby change table | Taxi rank | Emergency help point | Next service display | I37: This location is Independent Access | Lift | Escalator | Hearing loop | Wheelchair ramp boarding assistance | Platform edge tactiles | PA system for announcements | K37: 6.30am-10am | L37: 3.00-7pm | M37: =FALSE() -> FALSE | N37: -33.859163 | O37: 151.20255
A38: Barangaroo Wharf | B38: 2000441 | C38: 10102039 | D38: Wulugul Walk, Barangaroo NSW 2000 | E38: 2000 | F38: parsed from address | G38: Ferry | H38: Emergency help point | Next service display | Opal card top up or single trip ticket machine (Cash or Card Payment) | Opal card top up or single trip ticket machine (Card Payment only) | I38: This location is Independent Access | Wheelchair ramp boarding assistance | Hearing loop | PA system for announcements | Wharf edge tactiles | M38: =FALSE() -> FALSE | N38: -33.864377 | O38: 151.20059
A39: Bardwell Park Station | B39: 220710 | C39: 10101410 | D39: Hartill-Law Ave, Bardwell Park NSW 2207 | E39: 2207 | F39: parsed from address | G39: Train, Bus | H39: Commuter car park | Kiss and ride stopping area | Toilets | Wheelchair accessible toilet | Baby change table | Emergency help point | Next service display | Opal card top up or single trip ticket machine (Cash or Card Payment) | I39: This location is Independent Access | Wheelchair ramp boarding assistance | Hearing loop | PA system for announcements | Platform edge tactiles | Stairs | Lift | J39: 02 9563 7428 | K39: 6.30am-10am | L39: 3pm-7pm | M39: =FALSE() -> FALSE | N39: -33.931617 | O39: 151.12486
A40: Barellan Coach Stop | B40: 266592 | C40: 10102846 | D40: Burley Griffin Way before Myall St, Barellan NSW 2665 | E40: 2665 | F40: parsed from address | G40: Coach | I40: This location is Not Accessible | | M40: =FALSE() -> FALSE | N40: -34.284782 | O40: 146.57203
...

Sheet Sports_Facilities
A1: FacilityName | B1: Suburb | C1: Postcode | D1: FacilityType | E1: Status | F1: Owner | G1: Sports & activities
A2: Alan Davidson Oval | B2: Alexandria | C2: 2015 | D2: Sports field | E2: Current | F2: City of Sydney | G2: AFL, Cricket
A3: Alexandria Park and Oval | B3: Alexandria | C3: 2015 | D3: Sports field, Tennis courts | E3: Current | F3: City of Sydney | G3: Basketball, Cricket, Netball, Rugby, Soccer, TennisCourts
A4: Andrew (Boy) Charlton Pool | B4: Sydney | C4: 2000 | D4: Pool | E4: Currently closed for renovation | F4: City of Sydney | G4: Pool
A5: Beaconsfield Park | B5: Beaconsfield | C5: 2015 | D5: Tennis courts | E5: Current | F5: City of Sydney | G5: Basketball, TennisCourts
A6: Bourke Street Park | B6: Woolloomooloo | C6: 2011 | D6: Park | E6: Current | F6: City of Sydney | G6: OutdoorGym
A7: Centennial Parklands | B7: Centennial Park | C7: 2021 | D7: Park | E7: Not managed by City of Sydney | F7: Centennial Park and Moore Park Trust | G7: AFL, Cricket, Hockey, OutdoorGym, Rugby, Soccer
A8: Centennial Parklands Sports Centre | B8: Moore Park | C8: 2021 | D8: Park | E8: Not managed by City of Sydney | F8: Centennial Park and Moore Park Trust | G8: AFL, Athletics, Basketball, Netball, Pickleball, Rugby, Soccer, TennisCourts
A9: Cliff Noble Community Centre | B9: Alexandria | C9: 2015 | D9: Community centre | E9: Current | F9: City of Sydney | G9: CityPrograms, TableTennis
A10: Cook + Phillip Park | B10: Sydney | C10: 2000 | D10: Park | E10: Current | F10: City of Sydney | G10: Basketball
A11: Cook + Phillip Park Pool | B11: Sydney | C11: 2000 | D11: Pool | E11: Current | F11: City of Sydney | G11: Badminton, Basketball, Futsal, IndoorGym, Netball, Pickleball, Pool, Volleyball
A12: Eddie Ward Park | B12: Surry Hills | C12: 2010 | D12: Park | E12: Current | F12: City of Sydney | G12: SkatePark, TableTennis
A13: Erskineville Oval | B13: Erskineville | C13: 2043 | D13: Sports field | E13: Current | F13: City of Sydney | G13: Athletics, Cricket, Rugby
... A71: Wulaba Park | B71: Waterloo | C71: 2017 | D71: Park | E71: Current | F71: City of Sydney | G71: TableTennis

Sheet Taxi_Ranks
A1: Rank_name | B1: Postcode | C1: Postcode_source | D1: Postcode_confidence | E1: Nearest_ref_m | F1: Latitude | G1: Longitude
A2: Allambie rank, Allambie Rd | B2: 2100 | C2: inferred: nearest EV/transport point | D2: high (<300m) | E2: 112 | F2: -33.765369 | G2: 151.24999
A3: Arncliffe, Firth St | B3: 2205 | C3: inferred: nearest EV/transport point | D3: high (<300m) | E3: 43 | F3: -33.936614 | G3: 151.14687
A4: Artarmon rank, Elizabeth St | B4: 2064 | C4: inferred: nearest EV/transport point | D4: high (<300m) | E4: 72 | F4: -33.808261 | G4: 151.1854
A5: Ashfield Rank, Hercules St | B5: 2131 | C5: inferred: nearest EV/transport point | D5: high (<300m) | E5: 66 | F5: -33.888146 | G5: 151.12551
A6: Auburn South Rank, South Parade | B6: 2144 | C6: inferred: nearest EV/transport point | D6: high (<300m) | E6: 44 | F6: -33.849239 | G6: 151.0324
A7: Avalon rank, Old Barrenjoey rd Avalon | B7: 2106 | C7: inferred: nearest EV/transport point | D7: low (>1km) | E7: 2711 | F7: -33.635878 | G7: 151.32961
A8: Balgowlah rank, Condamine St | B8: 2093 | C8: inferred: nearest EV/transport point | D8: high (<300m) | E8: 168 | F8: -33.794565 | G8: 151.26477
A9: Balgowlah Stocklands, Condamine St | B9: 2093 | C9: inferred: nearest EV/transport point | D9: high (<300m) | E9: 87 | F9: -33.793587 | G9: 151.26501
A10: Balmain Rank, Darling St | B10: 2041 | C10: inferred: nearest EV/transport point | D10: high (<300m) | E10: 70 | F10: -33.857399 | G10: 151.18071
A11: Bankstown Rank, North Terrace | B11: 2200 | C11: inferred: nearest EV/transport point | D11: high (<300m) | E11: 58 | F11: -33.917361 | G11: 151.03452
A12: Baulkham Hills Rank, Central Pl | B12: 2153 | C12: inferred: nearest EV/transport point | D12: high (<300m) | E12: 110 | F12: -33.7599 | G12: 150.99197
A13: Beecroft Rank, Hannah St | B13: 2119 | C13: inferred: nearest EV/transport point | D13: high (<300m) | E13: 93 | F13: -33.749355 | G13: 151.0656
... A199: Woolloomooloo rank, Cowper Wharf Rd | B199: 2011 | C199: inferred: nearest EV/transport point | D199: medium (300m-1km) | E199: 579 | F199: -33.869144 | G199: 151.22004

Sheet All_Points
A1: Dataset | B1: Name | C1: Address | D1: Postcode | E1: Postcode_source | F1: Latitude | G1: Longitude | H1: Detail
A2: EV charger | B2: NRMA charger | C2: 129 Pacific Hwy Ourimbah NSW 2258 | D2: 2258 | E2: parsed from address | F2: -33.353198 | G2: 151.36903 | H2: NRMA | Upcoming | 4 plug(s)
A3: EV charger | B3: NRMA charger | C3: 1-5 Hill Rd Sydney Olympic Park NSW 2127 | D3: 2127 | E3: parsed from address | F3: -33.846599 | G3: 151.05673 | H3: NRMA | Upcoming | 8 plug(s)
A4: EV charger | B4: NRMA charger | C4: 16 Cooper St Macksville NSW 2447 | D4: 2447 | E4: parsed from address | F4: -30.708461 | G4: 152.92007 | H4: NRMA | Upcoming | 4 plug(s)
A5: EV charger | B5: NRMA charger | C5: 2 Macquarie St Parramatta NSW 2150 | D5: 2150 | E5: parsed from address | F5: -33.81384 | G5: 150.99951 | H5: NRMA | Upcoming | 4 plug(s)
A6: EV charger | B6: NRMA charger | C6: 203 Holt Rd Taren Point NSW 2229 | D6: 2229 | E6: parsed from address | F6: -34.020269 | G6: 151.1171 | H6: NRMA | Upcoming | 4 plug(s)
A7: EV charger | B7: NRMA charger | C7: 25 Anglo Rd Campsie NSW 2194 | D7: 2194 | E7: parsed from address | F7: -33.911201 | G7: 151.10146 | H7: NRMA | Upcoming | 4 plug(s)
A8: EV charger | B8: NRMA charger | C8: 29 Church St, Maitland NSW 2320 | D8: 2320 | E8: parsed from address | F8: -32.732981 | G8: 151.55356 | H8: NRMA | Upcoming | 4 plug(s)
A9: EV charger | B9: NRMA charger | C9: 33 Village Cct Gregory Hills NSW 2557 | D9: 2557 | E9: parsed from address | F9: -34.026258 | G9: 150.77773 | H9: NRMA | Upcoming | 4 plug(s)
A10: EV charger | B10: NRMA charger | C10: 37-39 Bong Bong Street,, Dapto NSW 2023 | D10: 2023 | E10: parsed from address | F10: -34.494036 | G10: 150.79154 | H10: NRMA | Upcoming | 4 plug(s)
A11: EV charger | B11: NRMA charger | C11: 3A Cowell St Gladesville NSW 2111 | D11: 2111 | E11: parsed from address | F11: -33.832583 | G11: 151.12802 | H11: NRMA | Upcoming | 4 plug(s)
A12: EV charger | B12: NRMA charger | C12: 50 Pitt St Singleton NSW 2330 | D12: 2330 | E12: parsed from address | F12: -32.565117 | G12: 151.17446 | H12: NRMA | Upcoming | 4 plug(s)
A13: EV charger | B13: NRMA charger | C13: 57 Manchester Rd Gymea NSW 2227 | D13: 2227 | E13: parsed from address | F13: -34.032498 | G13: 151.08811 | H13: NRMA | Upcoming | 4 plug(s)
... A2756: Transport stop | B2756: Zig Zag Station | C2756: Inch St, Clarence NSW 2790 | D2756: 2790 | E2756: parsed from address | F2756: -33.47181 | G2756: 150.20209 | H2756: Train
A2757: Sports facility | B2757: Alan Davidson Oval | C2757: Alexandria | D2757: 2015 | E2757: original | H2757: Sports field
A2758: Sports facility | B2758: Alexandria Park and Oval | C2758: Alexandria | D2758: 2015 | E2758: original | H2758: Sports field, Tennis courts
A2759: Sports facility | B2759: Andrew (Boy) Charlton Pool | C2759: Sydney | D2759: 2000 | E2759: original | H2759: Pool
A2760: Sports facility | B2760: Beaconsfield Park | C2760: Beaconsfield | D2760: 2015 | E2760: original | H2760: Tennis courts
A2761: Sports facility | B2761: Bourke Street Park | C2761: Woolloomooloo | D2761: 2011 | E2761: original | H2761: Park
A2762: Sports facility | B2762: Centennial Parklands | C2762: Centennial Park | D2762: 2021 | E2762: original | H2762: Park
A2763: Sports facility | B2763: Centennial Parklands Sports Centre | C2763: Moore Park | D2763: 2021 | E2763: original | H2763: Park
A2764: Sports facility | B2764: Cliff Noble Community Centre | C2764: Alexandria | D2764: 2015 | E2764: original | H2764: Community centre
A2765: Sports facility | B2765: Cook + Phillip Park | C2765: Sydney | D2765: 2000 | E2765: original | H2765: Park
A2766: Sports facility | B2766: Cook + Phillip Park Pool | C2766: Sydney | D2766: 2000 | E2766: original | H2766: Pool
A2767: Sports facility | B2767: Eddie Ward Park | C2767: Surry Hills | D2767: 2010 | E2767: original | H2767: Park
A2768: Sports facility | B2768: Erskineville Oval | C2768: Erskineville | D2768: 2043 | E2768: original | H2768: Sports field
... A2826: Sports facility | B2826: Wulaba Park | C2826: Waterloo | D2826: 2017 | E2826: original | H2826: Park
A2827: Taxi rank | B2827: Allambie rank, Allambie Rd | D2827: 2100 | E2827: inferred: nearest EV/transport point (high (<300m)) | F2827: -33.765369 | G2827: 151.24999
A2828: Taxi rank | B2828: Arncliffe, Firth St | D2828: 2205 | E2828: inferred: nearest EV/transport point (high (<300m)) | F2828: -33.936614 | G2828: 151.14687
A2829: Taxi rank | B2829: Artarmon rank, Elizabeth St | D2829: 2064 | E2829: inferred: nearest EV/transport point (high (<300m)) | F2829: -33.808261 | G2829: 151.1854
A2830: Taxi rank | B2830: Ashfield Rank, Hercules St | D2830: 2131 | E2830: inferred: nearest EV/transport point (high (<300m)) | F2830: -33.888146 | G2830: 151.12551
A2831: Taxi rank | B2831: Auburn South Rank, South Parade | D2831: 2144 | E2831: inferred: nearest EV/transport point (high (<300m)) | F2831: -33.849239 | G2831: 151.0324
A2832: Taxi rank | B2832: Avalon rank, Old Barrenjoey rd Avalon | D2832: 2106 | E2832: inferred: nearest EV/transport point (low (>1km)) | F2832: -33.635878 | G2832: 151.32961
A2833: Taxi rank | B2833: Balgowlah rank, Condamine St | D2833: 2093 | E2833: inferred: nearest EV/transport point (high (<300m)) | F2833: -33.794565 | G2833: 151.26477
A2834: Taxi rank | B2834: Balgowlah Stocklands, Condamine St | D2834: 2093 | E2834: inferred: nearest EV/transport point (high (<300m)) | F2834: -33.793587 | G2834: 151.26501
A2835: Taxi rank | B2835: Balmain Rank, Darling St | D2835: 2041 | E2835: inferred: nearest EV/transport point (high (<300m)) | F2835: -33.857399 | G2835: 151.18071
A2836: Taxi rank | B2836: Bankstown Rank, North Terrace | D2836: 2200 | E2836: inferred: nearest EV/transport point (high (<300m)) | F2836: -33.917361 | G2836: 151.03452
A2837: Taxi rank | B2837: Baulkham Hills Rank, Central Pl | D2837: 2153 | E2837: inferred: nearest EV/transport point (high (<300m)) | F2837: -33.7599 | G2837: 150.99197
A2838: Taxi rank | B2838: Beecroft Rank, Hannah St | D2838: 2119 | E2838: inferred: nearest EV/transport point (high (<300m)) | F2838: -33.749355 | G2838: 151.0656
... A3024: Taxi rank | B3024: Woolloomooloo rank, Cowper Wharf Rd | D3024: 2011 | E3024: inferred: nearest EV/transport point (medium (300m-1km)) | F3024: -33.869144 | G3024: 151.22004
